Workbook

Sheet Instructions
B2: Model Instructions & Color Coding
B4: Purpose of This Model
B5: This discounted cash flow (DCF) model is designed to estimate the intrinsic value of Walton Hi-Tech Industries PLC. It integrates a detailed, driver-based forecast of the company's financial statements to determine a fair value per share, providing a data-driven foundation for investment analysis.
B9: Model Structure
B10: The model is built on a three-statement framework (Income Statement, Balance Sheet, Cash Flow Statement) and follows a logical flow:
B11: 1. Assumptions: All forecasting drivers are input here.
B12: 2. Financial Statements: The model projects future performance based on the drivers.
B13: 3. Valuation: The projected free cash flows are discounted to present value.
B15: Color Coding & Conventions
B16: To ensure clarity and ease of use, please adhere to the following color-coding system:
B18: Color | C18: Meaning
B19: Blue 🔵 | C19: Hard-coded Input / Assumption
B20: Black ⚫ | C20: Formula / Calculation
B21: Green 🟢 | C21: Link to Another Sheet

Sheet Assumptions
B2: Assumptions:
D4: 2026 | E4: 2027 | F4: 2028 | G4: 2029 | H4: 2030 | I4: 2031 | J4: 2032 | K4: 2033 | L4: 2034 | M4: 2035 | O4: Justification for DCF Model
C5: 1. REVENUE DRIVERS
C6: Freezer, Refrigerator & Compressor | D6: 0.03 | E6: 0.03 | F6: 0.03 | G6: 0.03 | H6: 0.03 | I6: 0.025 | J6: 0.025 | K6: 0.025 | L6: 0.02 | M6: 0.02 | O6: Moderate growth as mature market, 65–75% market share, low incremental volume growth & margin pressure due to VAT (7.5%)
C7: Air Conditioner | D7: 0.08 | E7: 0.07 | F7: 0.06 | G7: 0.06 | H7: 0.06 | I7: 0.055 | J7: 0.05 | K7: 0.05 | L7: 0.04 | M7: 0.04 | O7: Moderate but volatile growth as high sensitivity to economic cycles, climate change so long-term positive, VAT on AC
C8: Television | D8: 0.025 | E8: 0.02 | F8: 0.015 | G8: 0.015 | H8: 0.015 | I8: 0.01 | J8: 0.01 | K8: 0.01 | L8: 0.01 | M8: 0.01 | O8: Low growth as TV market shifting to imported premium brands (Samsung, LG), local players losing share & cost pressures from display imports
C9: Electrical Appliances (EAP) | D9: 0.1 | E9: 0.08 | F9: 0.07 | G9: 0.06 | H9: 0.05 | I9: 0.05 | J9: 0.05 | K9: 0.05 | L9: 0.05 | M9: 0.05 | O9: High growth as fast-growing segment & long-term growth still strong (middle-class growth)
C10: Home Appliances (HAP) | D10: 0.1 | E10: 0.09 | F10: 0.08 | G10: 0.07 | H10: 0.06 | I10: 0.05 | J10: 0.04 | K10: 0.04 | L10: 0.04 | M10: 0.04 | O10: Moderate growth as demand driven by middle class expansion
C11: Elevator | D11: 0.15 | E11: 0.14 | F11: 0.12 | G11: 0.1 | H11: 0.09 | I11: 0.08 | J11: 0.07 | K11: 0.06 | L11: 0.05 | M11: 0.04 | O11: Steady growth as long-term opportunity & dependent on construction sector (currently weak)
C12: Cable | D12: 0.12 | E12: 0.1 | F12: 0.08 | G12: 0.07 | H12: 0.06 | I12: 0.05 | J12: 0.05 | K12: 0.05 | L12: 0.05 | M12: 0.05 | O12: Steady growth as new factory integration and domestic substitution for imports
C13: Service Parts | D13: 0.18 | E13: 0.16 | F13: 0.14 | G13: 0.12 | H13: 0.1 | I13: 0.08 | J13: 0.07 | K13: 0.06 | L13: 0.06 | M13: 0.06 | O13: High sustainable growth as product installed base increasing & recurring, stable revenue source
C14: Others (Mold, Die, SBN) | D14: 0.08 | E14: 0.07 | F14: 0.06 | G14: 0.05 | H14: 0.05 | I14: 0.04 | J14: 0.04 | K14: 0.04 | L14: 0.04 | M14: 0.04 | O14: Moderate growth as B2B component sales
C15: WDIL IT Products | D15: 0 | E15: 0.3 | F15: 0.25 | G15: 0.2 | H15: 0.15 | I15: 0.1 | J15: 0.09 | K15: 0.08 | L15: 0.07 | M15: 0.06 | O15: Strong growth as strong IT portfolio, Bangladesh IT demand rising & synergies with Walton distribution
C16: Lithium Battery | E16: 0.25 | F16: 0.2 | G16: 0.15 | H16: 0.12 | I16: 0.1 | J16: 0.1 | K16: 0.08 | L16: 0.08 | M16: 0.08 | O16: High growth and then stabilizes in the long-term
C17: VAT Rate | D17: 0.08 | E17: 0.08 | F17: 0.08 | G17: 0.08 | H17: 0.08 | I17: 0.08 | J17: 0.08 | K17: 0.08 | L17: 0.08 | M17: 0.08 | O17: Kept constant per regulatory baseline
C18: WDIL IT Products Revenue | E18: =1015.91*(1+E15) -> 1320.683 | O18: Post-acquision revenue (Digi-Tech's revenue tk 1015.91 cr during 2024)
C19: Lithium Battery Revenue | D19: =(80000*8000)/10000000 -> 64 | O19: 80,000 units at a industry average price of tk. 8000 (estimated)
C21: 2. PROFITABILITY (% of Sales)
C22: COGS (% of Sales) | D22: 0.64 | E22: 0.64 | F22: 0.63 | G22: 0.63 | H22: 0.63 | I22: 0.62 | J22: 0.62 | K22: 0.6 | L22: 0.6 | M22: 0.6 | O22: Vertical Integration Benefit: Slight improvement from as cost controls and high-margin products (batteries) offset inflation.
C23: SG&A Expenses (% of Sales) | D23: 0.12 | E23: 0.117 | F23: 0.114 | G23: 0.112 | H23: 0.11 | I23: 0.1 | J23: 0.1 | K23: 0.1 | L23: 0.1 | M23: 0.1 | O23: High due to competition but improving gradually from 13.05% (2025) as merger synergies are realized.
C24: Merger integration costs (% sales) | E24: 50 | O24: One-time costs (50 crore) for Digi-Tech merger integration. (estimated 10-year amortization, starts FY 2027)
C25: D&A (% of Opening Assets) | D25: ='Ratio Analysis'!$I$44 -> 0.032232189 | E25: ='Ratio Analysis'!$I$44 -> 0.032232189 | F25: ='Ratio Analysis'!$I$44 -> 0.032232189 | G25: ='Ratio Analysis'!$I$44 -> 0.032232189 | H25: ='Ratio Analysis'!$I$44 -> 0.032232189 | I25: ='Ratio Analysis'!$I$44 -> 0.032232189 | J25: ='Ratio Analysis'!$I$44 -> 0.032232189 | K25: ='Ratio Analysis'!$I$44 -> 0.032232189 | ... M25: ='Ratio Analysis'!$I$44 -> 0.032232189 | O25: Historical Average
C26: Effective Tax Rate* | D26: =D42 -> 0 | E26: =D43 -> 0 | F26: =D44 -> 0 | G26: =D45 -> 0.0675 | H26: =D46 -> 0.0675 | I26: =H26 -> 0.0675 | J26: =D48 -> 0.225 | K26: =J26 -> 0.225 | L26: =K26 -> 0.225 | M26: =L26 -> 0.225 | O26: Graduated schedule based on disclosed changes to hi-tech park and manufacturing taxes.
C28: 4. CAPITAL & FINANCING
C29: CapEx % of Revenue | D29: ='Ratio Analysis'!$I$45 -> 0.078610096 | E29: ='Ratio Analysis'!$I$45 -> 0.078610096 | F29: ='Ratio Analysis'!$I$45 -> 0.078610096 | G29: ='Ratio Analysis'!$I$45 -> 0.078610096 | H29: ='Ratio Analysis'!$I$45 -> 0.078610096 | I29: ='Ratio Analysis'!$I$45 -> 0.078610096 | J29: ='Ratio Analysis'!$I$45 -> 0.078610096 | K29: ='Ratio Analysis'!$I$45 -> 0.078610096 | ... M29: ='Ratio Analysis'!$I$45 -> 0.078610096 | O29: In line with historical spending to support growth. [Regular Capex (% of revenue)]
C31: 5. Lithium Project CAPEX (BDT Crore) | D31: 113.66 | E31: 0 | F31: 0 | G31: 0 | H31: 0 | I31: 0 | J31: 0 | K31: 0 | L31: 0 | M31: 0 | O31: One-time CAPEX (BDT 113.66 Cr) for the battery project. [10-year amortization estimated]
C32: 6. Interest Rate on Debt | D32: =$D$54 -> 0.1192 | E32: =$D$54 -> 0.1192 | F32: =$D$54 -> 0.1192 | G32: =$D$54 -> 0.1192 | H32: =$D$54 -> 0.1192 | I32: =$D$54 -> 0.1192 | J32: =$D$54 -> 0.1192 | K32: =$D$54 -> 0.1192 | ... M32: =$D$54 -> 0.1192 | O32: A pre-tax cost of debt of 11.5% is assumed.
C33: 7. Dividend Payout Ratio | D33: 0.4 | E33: 0.4 | F33: 0.4 | G33: 0.4 | H33: 0.4 | I33: 0.4 | J33: 0.4 | K33: 0.4 | L33: 0.4 | M33: 0.4 | O33: New Policy: Reflects the permanent shift down from historical levels to retain earnings for growth.
C35: 8. Bangladesh 10Y Government Bond | D35: 0.1042 | O35: Bangladesh Bank [as of December 1st 2025]
C36: 9. Country Default Risk | D36: 0.081370487 | O36: NYU Stern Professor Aswath Damodaran, [July, 2025]
C37: 10. Equity Risk Premium (Bangladesh), ERP | D37: 0.1235 | O37: NYU Stern Professor Aswath Damodaran, [July, 2025]
C38: 11. Terminal Growth Rate (g) | D38: 0.04 | O38: A terminal growth rate of 4.0% is assumed. This is a conservative estimate that reflects the company's transition to a mature state by the end of the forecast period. It is below the long-term nominal GDP growth rate of Bangladesh, ensuring the company does not outgrow the economy in perpetuity.
C40: *Tax Rate Assumptions:
C41: Year | D41: Projected Tax Rate | E41: Justification for DCF Model
C42: FY 2026 | D42: 0 | E42: 100% tax exemption on business profits
C43: FY 2027 | D43: 0 | E43: 100% tax exemption on business profits
C44: FY 2028 | D44: 0 | E44: 100% tax exemption on business profits
C45: FY 2029 | D45: 0.0675 | E45: 70% tax exemption [ 22.5% * (1 - 0.70)]
C46: FY 2030 | D46: 0.0675 | E46: 70% tax exemption
C47: FY 2031 | D47: 0.0675 | E47: 70% tax exemption
...

Sheet Data
B2: Company Name | C2: Walton Hi-Tech Industries PLC
B3: Ticker: | C3: WALTONHIL
B4: Exchange: | C4: DSE
B5: Industry: | C5: Household Appliances
B6: Sector: | C6: Consumer Durables
B7: Face Value Per Share | C7: 10
B8: Current Share Price BDT | C8: 376.6
B9: Market Cap BDT (mn) | C9: 126057.57
B10: Shares Outstanding | C10: 333221177
B12: Income Statement
B13: Particulars | C13: 2019 | D13: 2020 | E13: 2021 | F13: 2022 | G13: 2023 | H13: 2024 | I13: 2025
B14: Sales revenue, net | C14: 51773237116 | D14: 41079248267 | E14: 69949925813 | F14: 81681681284 | G14: 66374271405 | H14: 75121154616 | I14: 70822475704
B15: Purchase | C15: 25277241920 | D15: 27803538581 | E15: 34270695635 | F15: 54876142790 | G15: 27467893812 | H15: 35248800151 | I15: 40996136389
B16: Cost of goods sold | C16: 30805628408 | D16: 25423508810 | E16: 43515489526 | F16: 55146823463 | G16: 43022875679 | H16: 46473228347 | I16: 45291678432
B17: Gross profit | C17: 20967608708 | D17: 15655739458 | E17: 26434436287 | F17: 26534857821 | G17: 23351395726 | H17: 28647926269 | I17: 25530797272
B18: Operating expenses | C18: 4067567881 | D18: 4652465206 | E18: 7089112340 | F18: 9184521666 | G18: 7782901962 | H18: 9850900444 | I18: 10709513504
B19: Selling & distribution expenses | C19: 3239850530 | D19: 3602364329 | E19: 6004705364 | F19: 7795190297 | G19: 6409291118 | H19: 8293518089 | I19: 9014387103
B20: Administrative expenses | C20: 827617351 | D20: 1050100877 | E20: 1084406976 | F20: 1389331369 | G20: 1373610844 | H20: 1557382355 | I20: 1695126401
B21: Depreciation | C21: 1331810588 | D21: 1541134096 | E21: 1676106067 | F21: 1924661890 | G21: 2141649331 | H21: 2508935876 | I21: 2952947737
B22: Amortization | C22: 18065970 | D22: 16341394 | E22: 11509797 | F22: 3946229 | G22: 5325234 | H22: 7022841 | I22: 7863317
B23: Operating profit | C23: 16900040827 | D23: 11003274252 | E23: 19345323947 | F23: 17350336155 | G23: 15571493764 | H23: 18797025825 | I23: 14821283768
B24: Other income/Miscellaneous income | C24: - | D24: - | E24: 84330796 | F24: 79765294 | G24: - | H24: -
B25: Non-operating income | C25: 98108941 | D25: -13131240 | E25: 511456412 | F25: 270571805 | G25: 201930120 | H25: -94598252 | I25: 266614954
B26: Finance income | C26: - | D26: - | E26: - | F26: - | G26: 32175044 | H26: 171221879 | I26: 290334678
B27: Finance costs | C27: 1493855820 | D27: 2243549865 | E27: 1245679758 | F27: 4738325106 | G27: 7535855991 | H27: 4591235836 | I27: 4484038732
B28: Profit before WPPF & Tax | C28: 15504373948 | D28: 8746593145 | E28: 18695434397 | F28: 12962348148 | G28: 8269742937 | H28: 14282421616 | I28: 10894194667
B29: Contribution to WPPF | C29: 738303521 | D29: 416504436 | E29: 890258781 | F29: 617254674 | G29: 393654464 | H29: 680115315 | I29: 518771175
B30: Profit before taxation | C30: 14766070427 | D30: 8330088710 | E30: 17805175616 | F30: 12345093474 | G30: 7876088473 | H30: 13602306301 | I30: 10375423492
B31: Income tax expense | C31: -1004931824 | D31: -1065594991 | E31: -1413136905 | F31: -178942918 | G31: -46309266 | H31: -37046974 | I31: -9263129
B32: Current Tax | C32: 848151353 | D32: -744892973 | E32: -2154739525 | F32: -65269058 | G32: -47752505 | H32: -57026659 | I32: -10227195
B33: Deferred Tax | C33: 156780471 | D33: -320702019 | E33: 741602620 | F33: -113673860 | G33: 1443239 | H33: 19979685 | I33: 964067
B34: Profit after tax | C34: 13761138603 | D34: 7264493719 | E34: 16392038712 | F34: 12166150557 | G34: 7826780005 | H34: 13565259327 | I34: 10366160364
B35: Earnings Per Share (EPS) | C35: 45.67 | D35: 24.21 | E35: 54.11 | F35: 40.16 | G35: 25.84 | H35: 44.78 | I35: 34.22
B38: Balance Sheet
B39: Particulars | C39: 2019 | D39: 2020 | E39: 2021 | F39: 2022 | G39: 2023 | H39: 2024 | I39: 2025
B40: Property, plant and equipment, net | C40: 57575574816 | D40: 59712087153 | E40: 62295280025 | F40: 65475136944 | G40: 68824874693 | H40: 70863873952 | I40: 77180420324
B41: Intangible assets | C41: 29332786 | D41: 23040791 | E41: 13362588 | F41: 13053850 | G41: 19217454 | H41: 16019226 | I41: 46082639
B42: Right-of-Use (ROU) asset | C42: - | D42: - | E42: - | F42: 207685994 | G42: 213136270 | H42: 201866955 | I42: 211722011
B43: Other Non-current assets | C43: 2131266850 | D43: 3771797260 | E43: 3943802332 | F43: 6446187658 | G43: 7351736250 | H43: 7437964575 | I43: 7247599337
B44: Investments | C44: 494171979 | D44: 594806302 | F44: - | G44: - | H44: -
...

Sheet Historical FS
B2: Historical Financial Statements - Walton Hi-Tech Industries PLC
B3: Years | C3: 2021 | D3: 2022 | E3: 2023 | F3: 2024 | G3: 2025 | H3: 7-Y Trend | I3: Average
I4: BDT in Crore
A5: # | B5: Income Statement
B6: Net Sales Revenue | C6: =IFERROR(Data!E188/10000000,0) -> 6994.9926 | D6: =IFERROR(Data!F188/10000000,0) -> 8168.1681 | E6: =IFERROR(Data!G188/10000000,0) -> 6637.4271 | F6: =IFERROR(Data!H188/10000000,0) -> 7512.1155 | G6: =IFERROR(Data!I188/10000000,0) -> 7082.2476 | I6: =AVERAGE(C6:G6) -> 7278.9902
B7: COGS | C7: =IFERROR(Data!E16/10000000,0) -> 4351.549 | D7: =IFERROR(Data!F16/10000000,0) -> 5514.6823 | E7: =IFERROR(Data!G16/10000000,0) -> 4302.2876 | F7: =IFERROR(Data!H16/10000000,0) -> 4647.3228 | G7: =IFERROR(Data!I16/10000000,0) -> 4529.1678 | I7: =AVERAGE(C7:G7) -> 4669.0019
B8: Gross Profit | C8: =IFERROR(Data!E17/10000000,0) -> 2643.4436 | D8: =IFERROR(Data!F17/10000000,0) -> 2653.4858 | E8: =IFERROR(Data!G17/10000000,0) -> 2335.1396 | F8: =IFERROR(Data!H17/10000000,0) -> 2864.7926 | G8: =IFERROR(Data!I17/10000000,0) -> 2553.0797 | I8: =AVERAGE(C8:G8) -> 2609.9883
B9: Operating expenses | C9: =C10+C11 -> 708.91123 | D9: =D10+D11 -> 918.45217 | E9: =E10+E11 -> 778.2902 | F9: =F10+F11 -> 985.09004 | G9: =G10+G11 -> 1070.9514 | I9: =AVERAGE(C9:G9) -> 892.339
B10: Selling & distribution expenses | C10: =IFERROR(Data!E19/10000000,0) -> 600.47054 | D10: =IFERROR(Data!F19/10000000,0) -> 779.51903 | E10: =IFERROR(Data!G19/10000000,0) -> 640.92911 | F10: =IFERROR(Data!H19/10000000,0) -> 829.35181 | G10: =IFERROR(Data!I19/10000000,0) -> 901.43871 | I10: =AVERAGE(C10:G10) -> 750.34184
B11: Administrative expenses | C11: =IFERROR(Data!E20/10000000,0) -> 108.4407 | D11: =IFERROR(Data!F20/10000000,0) -> 138.93314 | E11: =IFERROR(Data!G20/10000000,0) -> 137.36108 | F11: =IFERROR(Data!H20/10000000,0) -> 155.73824 | G11: =IFERROR(Data!I20/10000000,0) -> 169.51264 | I11: =AVERAGE(C11:G11) -> 141.99716
B12: EBITDA | C12: =C8-C9+C13 -> 2103.294 | D12: =D8-D9+D13 -> 1927.8944 | E12: =E8-E9+E13 -> 1771.5468 | F12: =F8-F9+F13 -> 2131.2985 | G12: =G8-G9+G13 -> 1778.2095 | I12: =AVERAGE(C12:G12) -> 1942.4486
B13: Depreciation & Amortization | C13: =IFERROR((Data!E21+Data!E22)/10000000,0) -> 168.76159 | D13: =IFERROR((Data!F21+Data!F22)/10000000,0) -> 192.86081 | E13: =IFERROR((Data!G21+Data!G22)/10000000,0) -> 214.69746 | F13: =IFERROR((Data!H21+Data!H22)/10000000,0) -> 251.59587 | G13: =IFERROR((Data!I21+Data!I22)/10000000,0) -> 296.08111 | I13: =AVERAGE(C13:G13) -> 224.79937
B14: EBIT | C14: =C12-C13 -> 1934.5324 | D14: =D12-D13 -> 1735.0336 | E14: =E12-E13 -> 1556.8494 | F14: =F12-F13 -> 1879.7026 | G14: =G12-G13 -> 1482.1284 | I14: =AVERAGE(C14:G14) -> 1717.6493
B15: Other income | C15: =IFERROR(Data!E24/10000000,0) -> 8.4330796 | D15: =IFERROR(Data!F24/10000000,0) -> 7.9765294 | E15: =IFERROR(Data!G24/10000000,0) -> 0 | F15: =IFERROR(Data!H24/10000000,0) -> 0 | G15: =IFERROR(Data!I24/10000000,0) -> 0 | I15: =AVERAGE(C15:G15) -> 3.2819218
B16: Non-operating income | C16: =IFERROR(Data!E25/10000000,0) -> 51.145641 | D16: =IFERROR(Data!F25/10000000,0) -> 27.057181 | E16: =IFERROR(Data!G25/10000000,0) -> 20.193012 | F16: =IFERROR(Data!H25/10000000,0) -> -9.4598252 | G16: =IFERROR(Data!I25/10000000,0) -> 26.661495 | I16: =AVERAGE(C16:G16) -> 23.119501
B17: Finance income | C17: =IFERROR(Data!E26/10000000,0) -> 0 | D17: =IFERROR(Data!F26/10000000,0) -> 0 | E17: =IFERROR(Data!G26/10000000,0) -> 3.2175044 | F17: =IFERROR(Data!H26/10000000,0) -> 17.122188 | G17: =IFERROR(Data!I26/10000000,0) -> 29.033468 | I17: =AVERAGE(C17:G17) -> 9.874632
B18: Finance costs | C18: =IFERROR(Data!E27/10000000,0) -> 124.56798 | D18: =IFERROR(Data!F27/10000000,0) -> 473.83251 | E18: =IFERROR(Data!G27/10000000,0) -> 753.5856 | F18: =IFERROR(Data!H27/10000000,0) -> 459.12358 | G18: =IFERROR(Data!I27/10000000,0) -> 448.40387 | I18: =AVERAGE(C18:G18) -> 451.90271
B19: Profit before WPPF & Tax | C19: =IFERROR(Data!E28/10000000,0) -> 1869.5434 | D19: =IFERROR(Data!F28/10000000,0) -> 1296.2348 | E19: =IFERROR(Data!G28/10000000,0) -> 826.97429 | F19: =IFERROR(Data!H28/10000000,0) -> 1428.2422 | G19: =IFERROR(Data!I28/10000000,0) -> 1089.4195 | I19: =AVERAGE(C19:G19) -> 1302.0828
B20: Contribution to WPPF | C20: =IFERROR(Data!E29/10000000,0) -> 89.025878 | D20: =IFERROR(Data!F29/10000000,0) -> 61.725467 | E20: =IFERROR(Data!G29/10000000,0) -> 39.365446 | F20: =IFERROR(Data!H29/10000000,0) -> 68.011532 | G20: =IFERROR(Data!I29/10000000,0) -> 51.877117 | I20: =AVERAGE(C20:G20) -> 62.001088
B21: Earnings Before Tax | C21: =C19-C20 -> 1780.5176 | D21: =D19-D20 -> 1234.5093 | E21: =E19-E20 -> 787.60885 | F21: =F19-F20 -> 1360.2306 | G21: =G19-G20 -> 1037.5423 | I21: =AVERAGE(C21:G21) -> 1240.0817
B22: Tax | C22: =IFERROR(-Data!E31/10000000,0) -> 141.31369 | D22: =IFERROR(-Data!F31/10000000,0) -> 17.894292 | E22: =IFERROR(-Data!G31/10000000,0) -> 4.6309266 | F22: =IFERROR(-Data!H31/10000000,0) -> 3.7046974 | G22: =IFERROR(-Data!I31/10000000,0) -> 0.9263129 | I22: =AVERAGE(C22:G22) -> 33.693984
B23: Net Profit | C23: =IFERROR(Data!E34/10000000,0) -> 1639.2039 | D23: =IFERROR(Data!F34/10000000,0) -> 1216.6151 | E23: =IFERROR(Data!G34/10000000,0) -> 782.678 | F23: =IFERROR(Data!H34/10000000,0) -> 1356.5259 | G23: =IFERROR(Data!I34/10000000,0) -> 1036.616 | I23: =AVERAGE(C23:G23) -> 1206.3278
B24: Number of Shares Outstanding | C24: =IFERROR(Data!E79/10000000,0) -> 30.292834 | D24: =IFERROR(Data!F79/10000000,0) -> 30.292834 | E24: =IFERROR(Data!G79/10000000,0) -> 30.292834 | F24: =IFERROR(Data!H79/10000000,0) -> 30.292834 | G24: =IFERROR(Data!I79/10000000,0) -> 30.292834 | I24: =AVERAGE(C24:G24) -> 30.292834
B25: Earnings per Share | C25: =C23/C24 -> 54.111935 | D25: =D23/D24 -> 40.16181 | E25: =E23/E24 -> 25.837067 | F25: =F23/F24 -> 44.780423 | G25: =G23/G24 -> 34.219843 | I25: =AVERAGE(C25:G25) -> 39.822216
B26: EPS Growth % | D26: =(D25-C25)/C25 -> -0.25780126 | E26: =(E25-D25)/D25 -> -0.35667572 | F26: =(F25-E25)/E25 -> 0.73318521 | G26: =(G25-F25)/F25 -> -0.23583028 | I26: =AVERAGE(C26:G26) -> -0.029280514
B27: Dividend per Share | C27: =IFERROR(Data!E80,0) -> 25 | D27: =IFERROR(Data!F80,0) -> 25 | E27: =IFERROR(Data!G80,0) -> 30 | F27: =IFERROR(Data!H80,0) -> 35 | G27: =IFERROR(Data!I80,0) -> 17.5 | I27: =AVERAGE(C27:G27) -> 26.5
B28: Dividend payout ratio | C28: =C27/C25 -> 0.46200529 | D28: =D27/D25 -> 0.6224819 | E28: =E27/E25 -> 1.1611225 | F28: =F27/F25 -> 0.78159155 | G28: =G27/G25 -> 0.51139919 | I28: =AVERAGE(C28:G28) -> 0.70772008
B29: Retained Earnings | C29: =IFERROR(IF(C25>C27,1-C28,0),0) -> 0.53799471 | D29: =IFERROR(IF(D25>D27,1-D28,0),0) -> 0.3775181 | E29: =IFERROR(IF(E25>E27,1-E28,0),0) -> 0 | F29: =IFERROR(IF(F25>F27,1-F28,0),0) -> 0.21840845 | G29: =IFERROR(IF(G25>G27,1-G28,0),0) -> 0.48860081 | I29: =AVERAGE(C29:G29) -> 0.32450441
A31: # | B31: Balance Sheet
B32: Current Assets
B33: Cash & Cash Equivalents | C33: =IFERROR(Data!E53/10000000,0) -> 370.38257 | D33: =IFERROR(Data!F53/10000000,0) -> 232.13656 | E33: =IFERROR(Data!G53/10000000,0) -> 241.72322 | F33: =IFERROR(Data!H53/10000000,0) -> 654.73263 | G33: =IFERROR(Data!I53/10000000,0) -> 506.5457 | I33: =AVERAGE(C33:G33) -> 401.10414
B34: Short-term Investments | C34: =IFERROR(Data!E52/10000000,0) -> 136.55492 | D34: =IFERROR(Data!F52/10000000,0) -> 27.821501 | E34: =IFERROR(Data!G52/10000000,0) -> 31.351301 | F34: =IFERROR(Data!H52/10000000,0) -> 30.585054 | G34: =IFERROR(Data!I52/10000000,0) -> 29.732066 | I34: =AVERAGE(C34:G34) -> 51.208969
B35: Trade and Other Receivables | C35: =IFERROR(Data!E49/10000000,0) -> 3288.1935 | D35: =IFERROR(Data!F49/10000000,0) -> 4189.4179 | E35: =IFERROR(Data!G49/10000000,0) -> 3467.4948 | F35: =IFERROR(Data!H49/10000000,0) -> 3724.663 | G35: =IFERROR(Data!I49/10000000,0) -> 3606.624 | I35: =AVERAGE(C35:G35) -> 3655.2786
B36: Inventory | C36: =IFERROR(Data!E46/10000000,0) -> 2413.0562 | D36: =IFERROR(Data!F46/10000000,0) -> 3619.7619 | E36: =IFERROR(Data!G46/10000000,0) -> 2557.3533 | F36: =IFERROR(Data!H46/10000000,0) -> 2618.2664 | G36: =IFERROR(Data!I46/10000000,0) -> 2964.874 | I36: =AVERAGE(C36:G36) -> 2834.6624
B37: Advances, Deposits & Prepayments | C37: =IFERROR(Data!E51/10000000,0) -> 500.89681 | D37: =IFERROR(Data!F51/10000000,0) -> 553.65029 | E37: =IFERROR(Data!G51/10000000,0) -> 551.76371 | F37: =IFERROR(Data!H51/10000000,0) -> 767.17047 | G37: =IFERROR(Data!I51/10000000,0) -> 148.61545 | I37: =AVERAGE(C37:G37) -> 504.41934
B38: Investment in Securities | C38: =IFERROR(Data!E50/10000000,0) -> 110.60229 | D38: =IFERROR(Data!F50/10000000,0) -> 118.6988 | E38: =IFERROR(Data!G50/10000000,0) -> 103.37419 | F38: =IFERROR(Data!H50/10000000,0) -> 77.828393 | G38: =IFERROR(Data!I50/10000000,0) -> 36.58002 | I38: =AVERAGE(C38:G38) -> 89.416738
B39: Total Current Assets | C39: =SUM(C33:C38) -> 6819.6863 | D39: =SUM(D33:D38) -> 8741.487 | E39: =SUM(E33:E38) -> 6953.0606 | F39: =SUM(F33:F38) -> 7873.2459 | G39: =SUM(G33:G38) -> 7292.9712 | I39: =AVERAGE(C39:G39) -> 7536.0902
B40: Non-Current Assets
B41: Property, Plant & Equipment | C41: =IFERROR(Data!E40/10000000,0) -> 6229.528 | D41: =IFERROR(Data!F40/10000000,0) -> 6547.5137 | E41: =IFERROR(Data!G40/10000000,0) -> 6882.4875 | F41: =IFERROR(Data!H40/10000000,0) -> 7086.3874 | G41: =IFERROR(Data!I40/10000000,0) -> 7718.042 | I41: =AVERAGE(C41:G41) -> 6892.7917
B42: Right-of-Use Assets | C42: =IFERROR(Data!E42/10000000,0) -> 0 | D42: =IFERROR(Data!F42/10000000,0) -> 20.768599 | E42: =IFERROR(Data!G42/10000000,0) -> 21.313627 | F42: =IFERROR(Data!H42/10000000,0) -> 20.186695 | G42: =IFERROR(Data!I42/10000000,0) -> 21.172201 | I42: =AVERAGE(C42:G42) -> 16.688225
...

Sheet Revenue Forecast
B2: Revenue Forecast
B3: Years | C3: 2021 | D3: 2022 | E3: 2023 | F3: 2024 | G3: 2025 | H3: 2026 | I3: 2027 | J3: 2028 | K3: 2029 | L3: 2030 | M3: 2031 | N3: 2032 | O3: 2033 | P3: 2034 | Q3: 2035
Q4: BDT in Crore
B5: Freezer, Refrigerator & Compressor | C5: =IFERROR(Data!E177/10000000,0) -> 5216.6796 | D5: =IFERROR(Data!F177/10000000,0) -> 5818.2458 | E5: =IFERROR(Data!G177/10000000,0) -> 4454.7964 | F5: =IFERROR(Data!H177/10000000,0) -> 4658.8328 | G5: =IFERROR(Data!I177/10000000,0) -> 4759.5797 | H5: =G5*(1+Assumptions!D6) -> 4902.3671 | I5: =H5*(1+Assumptions!E6) -> 5049.4381 | J5: =I5*(1+Assumptions!F6) -> 5200.9213 | K5: =J5*(1+Assumptions!G6) -> 5356.9489 | L5: =K5*(1+Assumptions!H6) -> 5517.6574 | M5: =L5*(1+Assumptions!I6) -> 5655.5988 | N5: =M5*(1+Assumptions!J6) -> 5796.9888 | O5: =N5*(1+Assumptions!K6) -> 5941.9135 | ... Q5: =P5*(1+Assumptions!M6) -> 6181.9668
B6: Growth % | D6: =D5/C5-1 -> 0.1153159 | E6: =E5/D5-1 -> -0.23434028 | F6: =F5/E5-1 -> 0.045801503 | G6: =G5/F5-1 -> 0.021624936 | H6: =H5/G5-1 -> 0.03 | I6: =I5/H5-1 -> 0.03 | J6: =J5/I5-1 -> 0.03 | K6: =K5/J5-1 -> 0.03 | ... Q6: =Q5/P5-1 -> 0.02
B7: Air Conditioner | C7: =IFERROR(Data!E178/10000000,0) -> 366.38747 | D7: =IFERROR(Data!F178/10000000,0) -> 446.144 | E7: =IFERROR(Data!G178/10000000,0) -> 620.02496 | F7: =IFERROR(Data!H178/10000000,0) -> 965.08733 | G7: =IFERROR(Data!I178/10000000,0) -> 660.40191 | H7: =G7*(1+Assumptions!D7) -> 713.23406 | I7: =H7*(1+Assumptions!E7) -> 763.16044 | J7: =I7*(1+Assumptions!F7) -> 808.95007 | K7: =J7*(1+Assumptions!G7) -> 857.48707 | L7: =K7*(1+Assumptions!H7) -> 908.9363 | M7: =L7*(1+Assumptions!I7) -> 958.9278 | N7: =M7*(1+Assumptions!J7) -> 1006.8742 | O7: =N7*(1+Assumptions!K7) -> 1057.2179 | ... Q7: =P7*(1+Assumptions!M7) -> 1143.4869
B8: Growth % | D8: =D7/C7-1 -> 0.21768358 | E8: =E7/D7-1 -> 0.38974177 | F8: =F7/E7-1 -> 0.5565298 | G8: =G7/F7-1 -> -0.31570762 | H8: =H7/G7-1 -> 0.08 | I8: =I7/H7-1 -> 0.07 | J8: =J7/I7-1 -> 0.06 | K8: =K7/J7-1 -> 0.06 | ... Q8: =Q7/P7-1 -> 0.04
B9: Television | C9: =IFERROR(Data!E179/10000000,0) -> 827.78093 | D9: =IFERROR(Data!F179/10000000,0) -> 922.46286 | E9: =IFERROR(Data!G179/10000000,0) -> 610.69963 | F9: =IFERROR(Data!H179/10000000,0) -> 523.34811 | G9: =IFERROR(Data!I179/10000000,0) -> 411.47071 | H9: =G9*(1+Assumptions!D8) -> 421.75748 | I9: =H9*(1+Assumptions!E8) -> 430.19263 | J9: =I9*(1+Assumptions!F8) -> 436.64552 | K9: =J9*(1+Assumptions!G8) -> 443.1952 | L9: =K9*(1+Assumptions!H8) -> 449.84313 | M9: =L9*(1+Assumptions!I8) -> 454.34156 | N9: =M9*(1+Assumptions!J8) -> 458.88498 | O9: =N9*(1+Assumptions!K8) -> 463.47383 | ... Q9: =P9*(1+Assumptions!M8) -> 472.78965
B10: Growth % | D10: =D9/C9-1 -> 0.11438041 | E10: =E9/D9-1 -> -0.33796833 | F10: =F9/E9-1 -> -0.14303515 | G10: =G9/F9-1 -> -0.21377243 | H10: =H9/G9-1 -> 0.025 | I10: =I9/H9-1 -> 0.02 | J10: =J9/I9-1 -> 0.015 | K10: =K9/J9-1 -> 0.015 | ... Q10: =Q9/P9-1 -> 0.01
B11: Electrical Appliances (EAP) | C11: =IFERROR(Data!E180/10000000,0) -> 465.98171 | D11: =IFERROR(Data!F180/10000000,0) -> 701.83689 | E11: =IFERROR(Data!G180/10000000,0) -> 928.06174 | F11: =IFERROR(Data!H180/10000000,0) -> 1257.9784 | G11: =IFERROR(Data!I180/10000000,0) -> 1016.8628 | H11: =G11*(1+Assumptions!D9) -> 1118.549 | I11: =H11*(1+Assumptions!E9) -> 1208.0329 | J11: =I11*(1+Assumptions!F9) -> 1292.5953 | K11: =J11*(1+Assumptions!G9) -> 1370.151 | L11: =K11*(1+Assumptions!H9) -> 1438.6585 | M11: =L11*(1+Assumptions!I9) -> 1510.5914 | N11: =M11*(1+Assumptions!J9) -> 1586.121 | O11: =N11*(1+Assumptions!K9) -> 1665.4271 | ... Q11: =P11*(1+Assumptions!M9) -> 1836.1333
B12: Growth % | D12: =D11/C11-1 -> 0.50614687 | E12: =E11/D11-1 -> 0.32233251 | F12: =F11/E11-1 -> 0.35548995 | G12: =G11/F11-1 -> -0.19166912 | H12: =H11/G11-1 -> 0.1 | I12: =I11/H11-1 -> 0.08 | J12: =J11/I11-1 -> 0.07 | K12: =K11/J11-1 -> 0.06 | ... Q12: =Q11/P11-1 -> 0.05
B13: Home Appliances (HAP) | C13: =IFERROR(Data!E181/10000000,0) -> 319.6641 | D13: =IFERROR(Data!F181/10000000,0) -> 491.0798 | E13: =IFERROR(Data!G181/10000000,0) -> 351.64985 | F13: =IFERROR(Data!H181/10000000,0) -> 433.55145 | G13: =IFERROR(Data!I181/10000000,0) -> 462.02502 | H13: =G13*(1+Assumptions!D10) -> 508.22752 | I13: =H13*(1+Assumptions!E10) -> 553.968 | J13: =I13*(1+Assumptions!F10) -> 598.28544 | K13: =J13*(1+Assumptions!G10) -> 640.16542 | L13: =K13*(1+Assumptions!H10) -> 678.57534 | M13: =L13*(1+Assumptions!I10) -> 712.50411 | N13: =M13*(1+Assumptions!J10) -> 741.00428 | O13: =N13*(1+Assumptions!K10) -> 770.64445 | ... Q13: =P13*(1+Assumptions!M10) -> 833.52903
B14: Growth % | D14: =D13/C13-1 -> 0.53623697 | E14: =E13/D13-1 -> -0.28392525 | F14: =F13/E13-1 -> 0.23290668 | G14: =G13/F13-1 -> 0.06567518 | H14: =H13/G13-1 -> 0.1 | I14: =I13/H13-1 -> 0.09 | J14: =J13/I13-1 -> 0.08 | K14: =K13/J13-1 -> 0.07 | ... Q14: =Q13/P13-1 -> 0.04
B15: Elevator | D15: =IFERROR(Data!F182/10000000,0) -> 53.907451 | E15: =IFERROR(Data!G182/10000000,0) -> 104.11405 | F15: =IFERROR(Data!H182/10000000,0) -> 108.65919 | G15: =IFERROR(Data!I182/10000000,0) -> 161.07881 | H15: =G15*(1+Assumptions!D11) -> 185.24063 | I15: =H15*(1+Assumptions!E11) -> 211.17432 | J15: =I15*(1+Assumptions!F11) -> 236.51524 | K15: =J15*(1+Assumptions!G11) -> 260.16677 | L15: =K15*(1+Assumptions!H11) -> 283.58177 | M15: =L15*(1+Assumptions!I11) -> 306.26832 | N15: =M15*(1+Assumptions!J11) -> 327.7071 | O15: =N15*(1+Assumptions!K11) -> 347.36952 | ... Q15: =P15*(1+Assumptions!M11) -> 379.32752
B16: Growth % | E16: =E15/D15-1 -> 0.93134807 | F16: =F15/E15-1 -> 0.043655343 | G16: =G15/F15-1 -> 0.4824224 | H16: =H15/G15-1 -> 0.15 | I16: =I15/H15-1 -> 0.14 | J16: =J15/I15-1 -> 0.12 | K16: =K15/J15-1 -> 0.1 | L16: =L15/K15-1 -> 0.09 | ... Q16: =Q15/P15-1 -> 0.04
B17: Cable | G17: =IFERROR(Data!I183/10000000,0) -> 134.16057 | H17: =G17*(1+Assumptions!D12) -> 150.25984 | I17: =H17*(1+Assumptions!E12) -> 165.28582 | J17: =I17*(1+Assumptions!F12) -> 178.50869 | K17: =J17*(1+Assumptions!G12) -> 191.0043 | L17: =K17*(1+Assumptions!H12) -> 202.46456 | M17: =L17*(1+Assumptions!I12) -> 212.58778 | N17: =M17*(1+Assumptions!J12) -> 223.21717 | O17: =N17*(1+Assumptions!K12) -> 234.37803 | ... Q17: =P17*(1+Assumptions!M12) -> 258.40178
B18: Growth % | H18: =H17/G17-1 -> 0.12 | I18: =I17/H17-1 -> 0.1 | J18: =J17/I17-1 -> 0.08 | K18: =K17/J17-1 -> 0.07 | L18: =L17/K17-1 -> 0.06 | M18: =M17/L17-1 -> 0.05 | N18: =N17/M17-1 -> 0.05 | O18: =O17/N17-1 -> 0.05 | ... Q18: =Q17/P17-1 -> 0.05
B19: Service Parts | E19: =IFERROR(Data!G184/10000000,0) -> 3.6709551 | F19: =IFERROR(Data!H184/10000000,0) -> 27.632899 | G19: =IFERROR(Data!I184/10000000,0) -> 61.913861 | H19: =G19*(1+Assumptions!D13) -> 73.058356 | I19: =H19*(1+Assumptions!E13) -> 84.747693 | J19: =I19*(1+Assumptions!F13) -> 96.612369 | K19: =J19*(1+Assumptions!G13) -> 108.20585 | L19: =K19*(1+Assumptions!H13) -> 119.02644 | M19: =L19*(1+Assumptions!I13) -> 128.54855 | N19: =M19*(1+Assumptions!J13) -> 137.54695 | O19: =N19*(1+Assumptions!K13) -> 145.79977 | ... Q19: =P19*(1+Assumptions!M13) -> 163.82062
B20: Growth % | F20: =F19/E19-1 -> 6.5274414 | G20: =G19/F19-1 -> 1.240585 | H20: =H19/G19-1 -> 0.18 | I20: =I19/H19-1 -> 0.16 | J20: =J19/I19-1 -> 0.14 | K20: =K19/J19-1 -> 0.12 | L20: =L19/K19-1 -> 0.1 | M20: =M19/L19-1 -> 0.08 | ... Q20: =Q19/P19-1 -> 0.06
B21: Others (Mold, Die, SBN) | E21: =IFERROR(Data!G185/10000000,0) -> 3.76444 | F21: =IFERROR(Data!H185/10000000,0) -> 21.35821 | G21: =IFERROR(Data!I185/10000000,0) -> 24.244176 | H21: =G21*(1+Assumptions!D14) -> 26.18371 | I21: =H21*(1+Assumptions!E14) -> 28.01657 | J21: =I21*(1+Assumptions!F14) -> 29.697564 | K21: =J21*(1+Assumptions!G14) -> 31.182442 | L21: =K21*(1+Assumptions!H14) -> 32.741565 | M21: =L21*(1+Assumptions!I14) -> 34.051227 | N21: =M21*(1+Assumptions!J14) -> 35.413276 | O21: =N21*(1+Assumptions!K14) -> 36.829807 | ... Q21: =P21*(1+Assumptions!M14) -> 39.83512
B22: Growth % | F22: =F21/E21-1 -> 4.6736752 | G22: =G21/F21-1 -> 0.13512211 | H22: =H21/G21-1 -> 0.08 | I22: =I21/H21-1 -> 0.07 | J22: =J21/I21-1 -> 0.06 | K22: =K21/J21-1 -> 0.05 | L22: =L21/K21-1 -> 0.05 | M22: =M21/L21-1 -> 0.04 | ... Q22: =Q21/P21-1 -> 0.04
B23: WDIL IT Products | I23: =Assumptions!E18 -> 1320.683 | J23: =I23*(1+Assumptions!F15) -> 1650.8537 | K23: =J23*(1+Assumptions!G15) -> 1981.0245 | L23: =K23*(1+Assumptions!H15) -> 2278.1782 | M23: =L23*(1+Assumptions!I15) -> 2505.996 | N23: =M23*(1+Assumptions!J15) -> 2731.5356 | O23: =N23*(1+Assumptions!K15) -> 2950.0585 | P23: =O23*(1+Assumptions!L15) -> 3156.5626 | Q23: =P23*(1+Assumptions!M15) -> 3345.9563
B24: Growth % | J24: =J23/I23-1 -> 0.25 | K24: =K23/J23-1 -> 0.2 | L24: =L23/K23-1 -> 0.15 | M24: =M23/L23-1 -> 0.1 | N24: =N23/M23-1 -> 0.09 | O24: =O23/N23-1 -> 0.08 | P24: =P23/O23-1 -> 0.07 | Q24: =Q23/P23-1 -> 0.06
B25: Lithium Battery (WHIL) | H25: =Assumptions!D19 -> 64 | I25: =H25*(1+Assumptions!E16) -> 80 | J25: =I25*(1+Assumptions!F16) -> 96 | K25: =J25*(1+Assumptions!G16) -> 110.4 | L25: =K25*(1+Assumptions!H16) -> 123.648 | M25: =L25*(1+Assumptions!I16) -> 136.0128 | N25: =M25*(1+Assumptions!J16) -> 149.61408 | O25: =N25*(1+Assumptions!K16) -> 161.58321 | P25: =O25*(1+Assumptions!L16) -> 174.50986 | Q25: =P25*(1+Assumptions!M16) -> 188.47065
B26: Growth % | I26: =I25/H25-1 -> 0.25 | J26: =J25/I25-1 -> 0.2 | K26: =K25/J25-1 -> 0.15 | L26: =L25/K25-1 -> 0.12 | M26: =M25/L25-1 -> 0.1 | N26: =N25/M25-1 -> 0.1 | O26: =O25/N25-1 -> 0.08 | P26: =P25/O25-1 -> 0.08 | Q26: =Q25/P25-1 -> 0.08
B27: Total Revenue (before VAT) | C27: =C5+C7+C9+C11+C13+C15+C17+C19+C21+C23+C25 -> 7196.4938 | D27: =D5+D7+D9+D11+D13+D15+D17+D19+D21+D23+D25 -> 8433.6768 | E27: =E5+E7+E9+E11+E13+E15+E17+E19+E21+E23+E25 -> 7076.782 | F27: =F5+F7+F9+F11+F13+F15+F17+F19+F21+F23+F25 -> 7996.4483 | G27: =G5+G7+G9+G11+G13+G15+G17+G19+G21+G23+G25 -> 7691.7376 | H27: =H5+H7+H9+H11+H13+H15+H17+H19+H21+H23+H25 -> 8162.8778 | I27: =I5+I7+I9+I11+I13+I15+I17+I19+I21+I23+I25 -> 9894.6996 | J27: =J5+J7+J9+J11+J13+J15+J17+J19+J21+J23+J25 -> 10625.585 | ... Q27: =Q5+Q7+Q9+Q11+Q13+Q15+Q17+Q19+Q21+Q23+Q25 -> 14843.718
B28: VAT | C28: =IFERROR(Data!E187/10000000,0) -> -201.50126 | D28: =IFERROR(Data!F187/10000000,0) -> -265.50864 | E28: =IFERROR(Data!G187/10000000,0) -> -439.35489 | F28: =IFERROR(Data!H187/10000000,0) -> -484.33286 | G28: =IFERROR(Data!I187/10000000,0) -> -609.48999 | H28: =-H27*Assumptions!D17 -> -653.03022 | I28: =-I27*Assumptions!E17 -> -791.57597 | J28: =-J27*Assumptions!F17 -> -850.04682 | K28: =-K27*Assumptions!G17 -> -907.99452 | L28: =-L27*Assumptions!H17 -> -962.6649 | M28: =-M27*Assumptions!I17 -> -1009.2343 | N28: =-N27*Assumptions!J17 -> -1055.5926 | O28: =-O27*Assumptions!K17 -> -1101.9756 | ... Q28: =-Q27*Assumptions!M17 -> -1187.4974
B29: Net Revenue | C29: =SUM(C27:C28) -> 6994.9926 | D29: =SUM(D27:D28) -> 8168.1681 | E29: =SUM(E27:E28) -> 6637.4271 | F29: =SUM(F27:F28) -> 7512.1155 | G29: =SUM(G27:G28) -> 7082.2476 | H29: =SUM(H27:H28) -> 7509.8475 | I29: =SUM(I27:I28) -> 9103.1236 | J29: =SUM(J27:J28) -> 9775.5384 | ... Q29: =SUM(Q27:Q28) -> 13656.22
B30: YoY growth % | C30: 0.7028 | D30: =D29/C29-1 -> 0.16771648 | E30: =E29/D29-1 -> -0.18740322 | F30: =F29/E29-1 -> 0.13178123 | G30: =G29/F29-1 -> -0.057223281 | H30: =H29/G29-1 -> 0.06037631 | I30: =I29/H29-1 -> 0.21215824 | J30: =J29/I29-1 -> 0.073866377 | K30: =K29/J29-1 -> 0.068170012 | ... Q30: =Q29/P29-1 -> 0.037058138

Sheet Income Statement
B2: Income Statement - Walton Hi-Tech Industries PLC
B3: Years | C3: 2021 | D3: 2022 | E3: 2023 | F3: 2024 | G3: 2025 | H3: 2026 | I3: 2027 | J3: 2028 | K3: 2029 | L3: 2030 | M3: 2031 | N3: 2032 | O3: 2033 | P3: 2034 | Q3: 2035
Q4: BDT in Crore
B5: Income Statement
B6: Sales Revenue | C6: ='Revenue Forecast'!C29 -> 6994.9926 | D6: ='Revenue Forecast'!D29 -> 8168.1681 | E6: ='Revenue Forecast'!E29 -> 6637.4271 | F6: ='Revenue Forecast'!F29 -> 7512.1155 | G6: ='Revenue Forecast'!G29 -> 7082.2476 | H6: ='Revenue Forecast'!H29 -> 7509.8475 | I6: ='Revenue Forecast'!I29 -> 9103.1236 | J6: ='Revenue Forecast'!J29 -> 9775.5384 | ... Q6: ='Revenue Forecast'!Q29 -> 13656.22
B7: Revenue Growth % | C7: ='Revenue Forecast'!C30 -> 0.7028 | D7: ='Revenue Forecast'!D30 -> 0.16771648 | E7: ='Revenue Forecast'!E30 -> -0.18740322 | F7: ='Revenue Forecast'!F30 -> 0.13178123 | G7: ='Revenue Forecast'!G30 -> -0.057223281 | H7: ='Revenue Forecast'!H30 -> 0.06037631 | I7: ='Revenue Forecast'!I30 -> 0.21215824 | J7: ='Revenue Forecast'!J30 -> 0.073866377 | ... Q7: ='Revenue Forecast'!Q30 -> 0.037058138
B8: COGS | C8: ='Historical FS'!C7 -> 4351.549 | D8: ='Historical FS'!D7 -> 5514.6823 | E8: ='Historical FS'!E7 -> 4302.2876 | F8: ='Historical FS'!F7 -> 4647.3228 | G8: ='Historical FS'!G7 -> 4529.1678 | H8: =H6*Assumptions!D22 -> 4806.3024 | I8: =I6*Assumptions!E22 -> 5825.9991 | J8: =J6*Assumptions!F22 -> 6158.5892 | K8: =K6*Assumptions!G22 -> 6578.4203 | L8: =L6*Assumptions!H22 -> 6974.5072 | M8: =M6*Assumptions!I22 -> 7195.8404 | N8: =N6*Assumptions!J22 -> 7526.3752 | O8: =O6*Assumptions!K22 -> 7603.632 | ... Q8: =Q6*Assumptions!M22 -> 8193.7322
B9: COGS % of Sales | C9: =C8/C6 -> 0.62209486 | D9: =D8/D6 -> 0.6751431 | E9: =E8/E6 -> 0.64818603 | F9: =F8/F6 -> 0.61864369 | G9: =G8/G6 -> 0.63950996 | H9: =H8/H6 -> 0.64 | I9: =I8/I6 -> 0.64 | J9: =J8/J6 -> 0.63 | ... Q9: =Q8/Q6 -> 0.6
B10: Gross Profit | C10: =C6-C8 -> 2643.4436 | D10: =D6-D8 -> 2653.4858 | E10: =E6-E8 -> 2335.1396 | F10: =F6-F8 -> 2864.7926 | G10: =G6-G8 -> 2553.0797 | H10: =H6-H8 -> 2703.5451 | I10: =I6-I8 -> 3277.1245 | J10: =J6-J8 -> 3616.9492 | ... Q10: =Q6-Q8 -> 5462.4881
B11: Gross Margin % | C11: =C10/C6 -> 0.37790514 | D11: =D10/D6 -> 0.3248569 | E11: =E10/E6 -> 0.35181397 | F11: =F10/F6 -> 0.38135631 | G11: =G10/G6 -> 0.36049004 | H11: =H10/H6 -> 0.36 | I11: =I10/I6 -> 0.36 | J11: =J10/J6 -> 0.37 | ... Q11: =Q10/Q6 -> 0.4
B13: SG&A | C13: ='Historical FS'!C10+'Historical FS'!C11 -> 708.91123 | D13: ='Historical FS'!D10+'Historical FS'!D11 -> 918.45217 | E13: ='Historical FS'!E10+'Historical FS'!E11 -> 778.2902 | F13: ='Historical FS'!F10+'Historical FS'!F11 -> 985.09004 | G13: ='Historical FS'!G10+'Historical FS'!G11 -> 1070.9514 | H13: =H6*Assumptions!D23 -> 901.18171 | I13: =I6*Assumptions!E23 -> 1065.0655 | J13: =J6*Assumptions!F23 -> 1114.4114 | K13: =K6*Assumptions!G23 -> 1169.4969 | L13: =L6*Assumptions!H23 -> 1217.7711 | M13: =M6*Assumptions!I23 -> 1160.6194 | N13: =N6*Assumptions!J23 -> 1213.9315 | O13: =O6*Assumptions!K23 -> 1267.272 | ... Q13: =Q6*Assumptions!M23 -> 1365.622
B14: SG&A % of Sales | C14: =C13/C6 -> 0.10134553 | D14: =D13/D6 -> 0.11244286 | E14: =E13/E6 -> 0.11725781 | F14: =F13/F6 -> 0.13113351 | G14: =G13/G6 -> 0.15121631 | H14: =H13/H6 -> 0.12 | I14: =I13/I6 -> 0.117 | J14: =J13/J6 -> 0.114 | ... Q14: =Q13/Q6 -> 0.1
B15: Merger Integration Costs | C15: 0 | D15: 0 | E15: 0 | F15: 0 | G15: 0 | H15: 0 | I15: =Assumptions!E24 -> 50 | J15: 0 | K15: 0 | L15: 0 | M15: 0 | N15: 0 | O15: 0 | P15: 0 | Q15: 0
B16: Merger Integration Costs (% sales) | C16: =C15/C6 -> 0 | D16: =D15/D6 -> 0 | E16: =E15/E6 -> 0 | F16: =F15/F6 -> 0 | G16: =G15/G6 -> 0 | H16: =H15/H6 -> 0 | I16: =I15/I6 -> 0.0054926201 | J16: =J15/J6 -> 0 | ... Q16: =Q15/Q6 -> 0
B17: Total Operating Expenses | C17: =C13+C15 -> 708.91123 | D17: =D13+D15 -> 918.45217 | E17: =E13+E15 -> 778.2902 | F17: =F13+F15 -> 985.09004 | G17: =G13+G15 -> 1070.9514 | H17: =H13+H15 -> 901.18171 | I17: =I13+I15 -> 1115.0655 | J17: =J13+J15 -> 1114.4114 | ... Q17: =Q13+Q15 -> 1365.622
B18: OpEx % of Revenue | C18: =C17/C6 -> 0.10134553 | D18: =D17/D6 -> 0.11244286 | E18: =E17/E6 -> 0.11725781 | F18: =F17/F6 -> 0.13113351 | G18: =G17/G6 -> 0.15121631 | H18: =H17/H6 -> 0.12 | I18: =I17/I6 -> 0.12249262 | J18: =J17/J6 -> 0.114 | ... Q18: =Q17/Q6 -> 0.1
B19: EBITDA | C19: =C10-C17+C22 -> 2103.294 | D19: =D10-D17+D22 -> 1927.8944 | E19: =E10-E17+E22 -> 1771.5468 | F19: =F10-F17+F22 -> 2131.2985 | G19: =G10-G17+G22 -> 1778.2095 | H19: =H10-H17+H22 -> 2051.9638 | I19: =I10-I17+I22 -> 2426.306 | J19: =J10-J17+J22 -> 2781.3328 | ... Q19: =Q10-Q17+Q22 -> 4505.8397
B20: EBITDA Margin % | C20: =C19/C6 -> 0.30068566 | D20: =D19/D6 -> 0.23602531 | E20: =E19/E6 -> 0.26690264 | F20: =F19/F6 -> 0.28371482 | G20: =G19/G6 -> 0.25107983 | H20: =H19/H6 -> 0.27323641 | I20: =I19/I6 -> 0.26653554 | J20: =J19/J6 -> 0.28451965 | ... Q20: =Q19/Q6 -> 0.32994779
B22: Depreciation & Amortization | C22: ='Historical FS'!C13 -> 168.76159 | D22: ='Historical FS'!D13 -> 192.86081 | E22: ='Historical FS'!E13 -> 214.69746 | F22: ='Historical FS'!F13 -> 251.59587 | G22: ='Historical FS'!G13 -> 296.08111 | H22: ='Depreciation Schedule'!D10 -> 249.60035 | I22: ='Depreciation Schedule'!E10 -> 264.24696 | J22: ='Depreciation Schedule'!F10 -> 278.79498 | K22: ='Depreciation Schedule'!G10 -> 294.57782 | L22: ='Depreciation Schedule'!H10 -> 311.54046 | M22: ='Depreciation Schedule'!I10 -> 329.54936 | N22: ='Depreciation Schedule'!J10 -> 348.33475 | O22: ='Depreciation Schedule'!K10 -> 367.86546 | ... Q22: ='Depreciation Schedule'!M10 -> 408.97362
B23: EBIT | C23: =C19-C22 -> 1934.5324 | D23: =D19-D22 -> 1735.0336 | E23: =E19-E22 -> 1556.8494 | F23: =F19-F22 -> 1879.7026 | G23: =G19-G22 -> 1482.1284 | H23: =H19-H22 -> 1802.3634 | I23: =I19-I22 -> 2162.059 | J23: =J19-J22 -> 2502.5378 | ... Q23: =Q19-Q22 -> 4096.8661
B24: EBIT Margin % | C24: =C23/C6 -> 0.27655961 | D24: =D23/D6 -> 0.21241404 | E24: =E23/E6 -> 0.23455615 | F24: =F23/F6 -> 0.2502228 | G24: =G23/G6 -> 0.20927373 | H24: =H23/H6 -> 0.24 | I24: =I23/I6 -> 0.23750738 | J24: =J23/J6 -> 0.256 | ... Q24: =Q23/Q6 -> 0.3
B26: Other Income/(Expense) | C26: ='Historical FS'!C15+'Historical FS'!C16 -> 59.578721 | D26: ='Historical FS'!D15+'Historical FS'!D16 -> 35.03371 | E26: ='Historical FS'!E15+'Historical FS'!E16 -> 20.193012 | F26: ='Historical FS'!F15+'Historical FS'!F16 -> -9.4598252 | G26: ='Historical FS'!G15+'Historical FS'!G16 -> 26.661495 | H26: 0 | I26: 0 | J26: 0 | K26: 0 | L26: 0 | M26: 0 | N26: 0 | O26: 0 | P26: 0 | Q26: 0
B27: Finance Income | C27: ='Historical FS'!C17 -> 0 | D27: ='Historical FS'!D17 -> 0 | E27: ='Historical FS'!E17 -> 3.2175044 | F27: ='Historical FS'!F17 -> 17.122188 | G27: ='Historical FS'!G17 -> 29.033468 | H27: ='Debt Schedule'!D40 -> 30.920322 | I27: ='Debt Schedule'!E40 -> 27.609976 | J27: ='Debt Schedule'!F40 -> 17.525029 | K27: ='Debt Schedule'!G40 -> 24.225731 | L27: ='Debt Schedule'!H40 -> 31.676198 | M27: ='Debt Schedule'!I40 -> 46.562214 | N27: ='Debt Schedule'!J40 -> 62.44851 | O27: ='Debt Schedule'!K40 -> 79.235032 | ... Q27: ='Debt Schedule'!M40 -> 123.05536
B28: Finance Costs | C28: =-'Historical FS'!C18 -> -124.56798 | D28: =-'Historical FS'!D18 -> -473.83251 | E28: =-'Historical FS'!E18 -> -753.5856 | F28: =-'Historical FS'!F18 -> -459.12358 | G28: =-'Historical FS'!G18 -> -448.40387 | H28: =-'Debt Schedule'!D38 -> -437.98458 | I28: =-'Debt Schedule'!E38 -> -470.80363 | J28: =-'Debt Schedule'!F38 -> -484.65435 | K28: =-'Debt Schedule'!G38 -> -498.38115 | L28: =-'Debt Schedule'!H38 -> -511.3316 | M28: =-'Debt Schedule'!I38 -> -522.36307 | N28: =-'Debt Schedule'!J38 -> -533.34454 | O28: =-'Debt Schedule'!K38 -> -544.33187 | ... Q28: =-'Debt Schedule'!M38 -> -564.59048
B29: Profit Before WPPF & Tax | C29: =C23+SUM(C26:C28) -> 1869.5431 | D29: =D23+SUM(D26:D28) -> 1296.2348 | E29: =E23+SUM(E26:E28) -> 826.67429 | F29: =F23+SUM(F26:F28) -> 1428.2414 | G29: =G23+SUM(G26:G28) -> 1089.4195 | H29: =H23+SUM(H26:H28) -> 1395.2992 | I29: =I23+SUM(I26:I28) -> 1718.8654 | J29: =J23+SUM(J26:J28) -> 2035.4085 | ... Q29: =Q23+SUM(Q26:Q28) -> 3655.331
B31: Contribution to WPPF | C31: ='Historical FS'!C20 -> 89.025878 | D31: ='Historical FS'!D20 -> 61.725467 | E31: ='Historical FS'!E20 -> 39.365446 | F31: ='Historical FS'!F20 -> 68.011532 | G31: ='Historical FS'!G20 -> 51.877117 | H31: =H29*0.05 -> 69.764958 | I31: =I29*0.05 -> 85.943269 | J31: =J29*0.05 -> 101.77043 | K31: =K29*0.05 -> 110.99322 | L31: =L29*0.05 -> 119.93563 | M31: =M29*0.05 -> 138.69668 | N31: =N29*0.05 -> 146.40561 | O31: =O29*0.05 -> 166.83596 | ... Q31: =Q29*0.05 -> 182.76655
B32: Profit Before Taxation | C32: =C29-C31 -> 1780.5173 | D32: =D29-D31 -> 1234.5093 | E32: =E29-E31 -> 787.30885 | F32: =F29-F31 -> 1360.2298 | G32: =G29-G31 -> 1037.5423 | H32: =H29-H31 -> 1325.5342 | I32: =I29-I31 -> 1632.9221 | J32: =J29-J31 -> 1933.6381 | ... Q32: =Q29-Q31 -> 3472.5644
B34: Income Tax Expense | C34: ='Historical FS'!C22 -> 141.31369 | D34: ='Historical FS'!D22 -> 17.894292 | E34: ='Historical FS'!E22 -> 4.6309266 | F34: ='Historical FS'!F22 -> 3.7046974 | G34: ='Historical FS'!G22 -> 0.9263129 | H34: =H32*Assumptions!D26 -> 0 | I34: =I32*Assumptions!E26 -> 0 | J34: =J32*Assumptions!F26 -> 0 | K34: =K32*Assumptions!G26 -> 142.3488 | L34: =L32*Assumptions!H26 -> 153.81745 | M34: =M32*Assumptions!I26 -> 177.87849 | N34: =N32*Assumptions!J26 -> 625.88397 | O34: =O32*Assumptions!K26 -> 713.22372 | ... Q34: =Q32*Assumptions!M26 -> 781.327
B35: Net Profit | C35: =C32-C34 -> 1639.2036 | D35: =D32-D34 -> 1216.6151 | E35: =E32-E34 -> 782.67792 | F35: =F32-F34 -> 1356.5251 | G35: =G32-G34 -> 1036.616 | H35: =H32-H34 -> 1325.5342 | I35: =I32-I34 -> 1632.9221 | J35: =J32-J34 -> 1933.6381 | ... Q35: =Q32-Q34 -> 2691.2374
B36: Net Margin | C36: =C35/C6 -> 0.23433957 | D36: =D35/D6 -> 0.14894589 | E36: =E35/E6 -> 0.11791887 | F36: =F35/F6 -> 0.18057831 | G36: =G35/G6 -> 0.14636823 | H36: =H35/H6 -> 0.17650614 | I36: =I35/I6 -> 0.17938042 | J36: =J35/J6 -> 0.19780374 | ... Q36: =Q35/Q6 -> 0.19707045
B38: Number of Shares Outstanding | C38: ='Historical FS'!C24 -> 30.292834 | D38: ='Historical FS'!D24 -> 30.292834 | E38: ='Historical FS'!E24 -> 30.292834 | F38: ='Historical FS'!F24 -> 30.292834 | G38: ='Historical FS'!G24 -> 30.292834 | H38: =G38 -> 30.292834 | I38: =H38 -> 30.292834 | J38: =I38 -> 30.292834 | K38: =J38 -> 30.292834 | L38: =K38 -> 30.292834 | M38: =L38 -> 30.292834 | N38: =M38 -> 30.292834 | O38: =N38 -> 30.292834 | ... Q38: =P38 -> 30.292834
B39: Earnings Per Share (EPS) | C39: =C35/C38 -> 54.111925 | D39: =D35/D38 -> 40.16181 | E39: =E35/E38 -> 25.837065 | F39: =F35/F38 -> 44.780397 | G39: =G35/G38 -> 34.219843 | H39: =H35/H38 -> 43.757351 | I39: =I35/I38 -> 53.904567 | J39: =J35/J38 -> 63.831534 | ... Q39: =Q35/Q38 -> 88.840727
B40: EPS Growth % | D40: =(D39-C39)/C39 -> -0.25780112 | E40: =(E39-D39)/D39 -> -0.35667579 | F40: =(F39-E39)/E39 -> 0.73318436 | G40: =(G39-F39)/F39 -> -0.23582983 | H40: =(H39-G39)/G39 -> 0.2787128 | I40: =(I39-H39)/H39 -> 0.23189739 | J40: =(J39-I39)/I39 -> 0.18415818 | K40: =(K39-J39)/J39 -> 0.017006401 | ... Q40: =(Q39-P39)/P39 -> 0.045330186

Sheet Balance Sheet
B2: Balance Sheet - Walton Hi-Tech Industries PLC
B3: Years | C3: 2021 | D3: 2022 | E3: 2023 | F3: 2024 | G3: 2025 | H3: 2026 | I3: 2027 | J3: 2028 | K3: 2029 | L3: 2030 | M3: 2031 | N3: 2032 | O3: 2033 | P3: 2034 | Q3: 2035
Q4: BDT in Crore
B5: Balance Sheet
B6: Current Assets
B7: Cash & Cash Equivalents | C7: ='Historical FS'!C33 -> 370.38257 | D7: ='Historical FS'!D33 -> 232.13656 | E7: ='Historical FS'!E33 -> 241.72322 | F7: ='Historical FS'!F33 -> 654.73263 | G7: ='Historical FS'!G33 -> 506.5457 | H7: =G7+'Cash Flow Statement'!H35 -> 1039.4704 | I7: =H7+'Cash Flow Statement'!I35 -> 341.02842 | J7: =I7+'Cash Flow Statement'!J35 -> 535.22305 | K7: =J7+'Cash Flow Statement'!K35 -> 676.06352 | L7: =K7+'Cash Flow Statement'!L35 -> 907.74635 | M7: =L7+'Cash Flow Statement'!M35 -> 1420.3644 | N7: =M7+'Cash Flow Statement'!N35 -> 1702.0611 | O7: =N7+'Cash Flow Statement'!O35 -> 2259.6905 | ... Q7: =P7+'Cash Flow Statement'!Q35 -> 3368.0057
B8: Short-term Investments | C8: ='Historical FS'!C34 -> 136.55492 | D8: ='Historical FS'!D34 -> 27.821501 | E8: ='Historical FS'!E34 -> 31.351301 | F8: ='Historical FS'!F34 -> 30.585054 | G8: ='Historical FS'!G34 -> 29.732066 | H8: =G8 -> 29.732066 | I8: =H8 -> 29.732066 | J8: =I8 -> 29.732066 | K8: =J8 -> 29.732066 | L8: =K8 -> 29.732066 | M8: =L8 -> 29.732066 | N8: =M8 -> 29.732066 | O8: =N8 -> 29.732066 | ... Q8: =P8 -> 29.732066
B9: Trade and Other Receivables | C9: ='Historical FS'!C35 -> 3288.1935 | D9: ='Historical FS'!D35 -> 4189.4179 | E9: ='Historical FS'!E35 -> 3467.4948 | F9: ='Historical FS'!F35 -> 3724.663 | G9: ='Historical FS'!G35 -> 3606.624 | H9: =G9-'Cash Flow Statement'!H10 -> 3703.4865 | I9: =H9-'Cash Flow Statement'!I10 -> 4489.2116 | J9: =I9-'Cash Flow Statement'!J10 -> 4820.8134 | K9: =J9-'Cash Flow Statement'!K10 -> 5149.4484 | L9: =K9-'Cash Flow Statement'!L10 -> 5459.4968 | M9: =L9-'Cash Flow Statement'!M10 -> 5723.6026 | N9: =M9-'Cash Flow Statement'!N10 -> 5986.5114 | O9: =N9-'Cash Flow Statement'!O10 -> 6249.5605 | ... Q9: =P9-'Cash Flow Statement'!Q10 -> 6734.5744
B10: Inventory | C10: ='Historical FS'!C36 -> 2413.0562 | D10: ='Historical FS'!D36 -> 3619.7619 | E10: ='Historical FS'!E36 -> 2557.3533 | F10: ='Historical FS'!F36 -> 2618.2664 | G10: ='Historical FS'!G36 -> 2964.874 | H10: =G10-'Cash Flow Statement'!H11 -> 2633.5904 | I10: =H10-'Cash Flow Statement'!I11 -> 3192.3283 | J10: =I10-'Cash Flow Statement'!J11 -> 3374.5694 | K10: =J10-'Cash Flow Statement'!K11 -> 3604.6138 | L10: =K10-'Cash Flow Statement'!L11 -> 3821.6478 | M10: =L10-'Cash Flow Statement'!M11 -> 3942.9262 | N10: =M10-'Cash Flow Statement'!N11 -> 4124.0412 | O10: =N10-'Cash Flow Statement'!O11 -> 4166.3737 | ... Q10: =P10-'Cash Flow Statement'!Q11 -> 4489.7163
B11: Advances, Deposits & Prepayments | C11: ='Historical FS'!C37 -> 500.89681 | D11: ='Historical FS'!D37 -> 553.65029 | E11: ='Historical FS'!E37 -> 551.76371 | F11: ='Historical FS'!F37 -> 767.17047 | G11: ='Historical FS'!G37 -> 148.61545 | H11: =G11-'Cash Flow Statement'!H12 -> 370.34865 | I11: =H11-'Cash Flow Statement'!I12 -> 437.69814 | J11: =I11-'Cash Flow Statement'!J12 -> 457.97728 | K11: =J11-'Cash Flow Statement'!K12 -> 480.61518 | L11: =K11-'Cash Flow Statement'!L12 -> 500.45387 | M11: =L11-'Cash Flow Statement'!M12 -> 476.96688 | N11: =M11-'Cash Flow Statement'!N12 -> 498.87595 | O11: =N11-'Cash Flow Statement'!O12 -> 520.79671 | ... Q11: =P11-'Cash Flow Statement'!Q12 -> 561.21453
B12: Investment in Securities | C12: ='Historical FS'!C38 -> 110.60229 | D12: ='Historical FS'!D38 -> 118.6988 | E12: ='Historical FS'!E38 -> 103.37419 | F12: ='Historical FS'!F38 -> 77.828393 | G12: ='Historical FS'!G38 -> 36.58002 | H12: =G12 -> 36.58002 | I12: =H12 -> 36.58002 | J12: =I12 -> 36.58002 | K12: =J12 -> 36.58002 | L12: =K12 -> 36.58002 | M12: =L12 -> 36.58002 | N12: =M12 -> 36.58002 | O12: =N12 -> 36.58002 | ... Q12: =P12 -> 36.58002
B13: Total Current Assets | C13: =SUM(C7:C12) -> 6819.6863 | D13: =SUM(D7:D12) -> 8741.487 | E13: =SUM(E7:E12) -> 6953.0606 | F13: =SUM(F7:F12) -> 7873.2459 | G13: =SUM(G7:G12) -> 7292.9712 | H13: =SUM(H7:H12) -> 7813.208 | I13: =SUM(I7:I12) -> 8526.5786 | J13: =SUM(J7:J12) -> 9254.8953 | ... Q13: =SUM(Q7:Q12) -> 15219.823
B15: Non-Current Assets
B16: Property, Plant & Equipment | C16: ='Historical FS'!C41 -> 6229.528 | D16: ='Historical FS'!D41 -> 6547.5137 | E16: ='Historical FS'!E41 -> 6882.4875 | F16: ='Historical FS'!F41 -> 7086.3874 | G16: ='Historical FS'!G41 -> 7718.042
B17: Right-of-Use Assets | C17: ='Historical FS'!C42 -> 0 | D17: ='Historical FS'!D42 -> 20.768599 | E17: ='Historical FS'!E42 -> 21.313627 | F17: ='Historical FS'!F42 -> 20.186695 | G17: ='Historical FS'!G42 -> 21.172201
B18: Intangible Assets | C18: ='Historical FS'!C43 -> 1.3362588 | D18: ='Historical FS'!D43 -> 1.305385 | E18: ='Historical FS'!E43 -> 1.9217454 | F18: ='Historical FS'!F43 -> 1.6019226 | G18: ='Historical FS'!G43 -> 4.6082639
B19: Operating Assets, Net | C19: =SUM(C16:C18) -> 6230.8643 | D19: =SUM(D16:D18) -> 6569.5877 | E19: =SUM(E16:E18) -> 6905.7228 | F19: =SUM(F16:F18) -> 7108.176 | G19: =SUM(G16:G18) -> 7743.8225 | H19: ='Depreciation Schedule'!D11 -> 8198.232 | I19: ='Depreciation Schedule'!E11 -> 8649.5824 | J19: ='Depreciation Schedule'!F11 -> 9139.2435 | K19: ='Depreciation Schedule'!G11 -> 9665.5073 | L19: ='Depreciation Schedule'!H11 -> 10224.231 | M19: ='Depreciation Schedule'!I11 -> 10807.046 | N19: ='Depreciation Schedule'!J11 -> 11412.984 | O19: ='Depreciation Schedule'!K11 -> 12041.322 | ... Q19: ='Depreciation Schedule'!M11 -> 13352.903
B20: Other Non-current Assets | C20: ='Historical FS'!C44 -> 394.38023 | D20: ='Historical FS'!D44 -> 644.61877 | E20: ='Historical FS'!E44 -> 735.17363 | F20: ='Historical FS'!F44 -> 743.79646 | G20: ='Historical FS'!G44 -> 724.75993 | H20: =G20-'Cash Flow Statement'!H23-'Cash Flow Statement'!H15 -> 724.75993 | I20: =H20-'Cash Flow Statement'!I23-'Cash Flow Statement'!I15 -> 724.75993 | J20: =I20-'Cash Flow Statement'!J23-'Cash Flow Statement'!J15 -> 724.75993 | K20: =J20-'Cash Flow Statement'!K23-'Cash Flow Statement'!K15 -> 724.75993 | L20: =K20-'Cash Flow Statement'!L23-'Cash Flow Statement'!L15 -> 724.75993 | M20: =L20-'Cash Flow Statement'!M23-'Cash Flow Statement'!M15 -> 724.75993 | N20: =M20-'Cash Flow Statement'!N23-'Cash Flow Statement'!N15 -> 724.75993 | O20: =N20-'Cash Flow Statement'!O23-'Cash Flow Statement'!O15 -> 724.75993 | ... Q20: =P20-'Cash Flow Statement'!Q23-'Cash Flow Statement'!Q15 -> 724.75993
B21: Total Non-current Assets | C21: =SUM(C19:C20) -> 6625.2445 | D21: =SUM(D19:D20) -> 7214.2064 | E21: =SUM(E19:E20) -> 7640.8965 | F21: =SUM(F19:F20) -> 7851.9725 | G21: =SUM(G19:G20) -> 8468.5824 | H21: =SUM(H19:H20) -> 8922.9919 | I21: =SUM(I19:I20) -> 9374.3424 | J21: =SUM(J19:J20) -> 9864.0034 | ... Q21: =SUM(Q19:Q20) -> 14077.663
B23: Total Assets | C23: =C13+C21 -> 13444.931 | D23: =D13+D21 -> 15955.693 | E23: =E13+E21 -> 14593.957 | F23: =F13+F21 -> 15725.218 | G23: =G13+G21 -> 15761.554 | H23: =H13+H21 -> 16736.2 | I23: =I13+I21 -> 17900.921 | J23: =J13+J21 -> 19118.899 | ... Q23: =Q13+Q21 -> 29297.486
B25: Current Liabilities
B26: Accounts Payable | C26: ='Historical FS'!C48 -> 292.33228 | D26: ='Historical FS'!D48 -> 458.14572 | E26: ='Historical FS'!E48 -> 305.80097 | F26: ='Historical FS'!F48 -> 363.01136 | G26: ='Historical FS'!G48 -> 240.30518 | H26: =G26+'Cash Flow Statement'!H13 -> 395.03856 | I26: =H26+'Cash Flow Statement'!I13 -> 478.84924 | J26: =I26+'Cash Flow Statement'!J13 -> 506.18541 | K26: =J26+'Cash Flow Statement'!K13 -> 540.69208 | L26: =K26+'Cash Flow Statement'!L13 -> 573.24717 | M26: =L26+'Cash Flow Statement'!M13 -> 591.43893 | N26: =M26+'Cash Flow Statement'!N13 -> 618.60618 | O26: =N26+'Cash Flow Statement'!O13 -> 624.95605 | ... Q26: =P26+'Cash Flow Statement'!Q13 -> 673.45744
B27: Accrued Expenses | C27: ='Historical FS'!C49 -> 704.55801 | D27: ='Historical FS'!D49 -> 626.12201 | E27: ='Historical FS'!E49 -> 652.17449 | F27: ='Historical FS'!F49 -> 790.42642 | G27: ='Historical FS'!G49 -> 531.66138 | H27: =G27+'Cash Flow Statement'!H14 -> 556.25371 | I27: =H27+'Cash Flow Statement'!I14 -> 657.41084 | J27: =I27+'Cash Flow Statement'!J14 -> 687.86956 | K27: =J27+'Cash Flow Statement'!K14 -> 721.87108 | L27: =K27+'Cash Flow Statement'!L14 -> 751.66827 | M27: =L27+'Cash Flow Statement'!M14 -> 716.39144 | N27: =M27+'Cash Flow Statement'!N14 -> 749.29828 | O27: =N27+'Cash Flow Statement'!O14 -> 782.22266 | ... Q27: =P27+'Cash Flow Statement'!Q14 -> 842.92915
B28: Short-term Debt | C28: ='Historical FS'!C50 -> 2387.9415 | D28: ='Historical FS'!D50 -> 4265.9074 | E28: ='Historical FS'!E50 -> 2409.6052 | F28: ='Historical FS'!F50 -> 2124.3602 | G28: ='Historical FS'!G50 -> 1788.3977 | H28: ='Debt Schedule'!D15 -> 1788.3977 | I28: ='Debt Schedule'!E15 -> 1788.3977 | J28: ='Debt Schedule'!F15 -> 1788.3977 | K28: ='Debt Schedule'!G15 -> 1788.3977 | L28: ='Debt Schedule'!H15 -> 1788.3977 | M28: ='Debt Schedule'!I15 -> 1788.3977 | N28: ='Debt Schedule'!J15 -> 1788.3977 | O28: ='Debt Schedule'!K15 -> 1788.3977 | ... Q28: ='Debt Schedule'!M15 -> 1788.3977
B29: Current Portion of LT Debt | C29: ='Historical FS'!C51 -> 235.25441 | D29: ='Historical FS'!D51 -> 133.12941 | E29: ='Historical FS'!E51 -> 169.59514 | F29: ='Historical FS'!F51 -> 251.32621 | G29: ='Historical FS'!G51 -> 294.82176 | H29: =G29 -> 294.82176 | I29: =H29 -> 294.82176 | J29: =I29 -> 294.82176 | K29: =J29 -> 294.82176 | L29: =K29 -> 294.82176 | M29: =L29 -> 294.82176 | N29: =M29 -> 294.82176 | O29: =N29 -> 294.82176 | ... Q29: =P29 -> 294.82176
B30: Current Portion of Leases | C30: ='Historical FS'!C52 -> 0 | D30: ='Historical FS'!D52 -> 2.839484 | E30: ='Historical FS'!E52 -> 3.5666642 | F30: ='Historical FS'!F52 -> 4.1207819 | G30: ='Historical FS'!G52 -> 3.9624404 | H30: =G30 -> 3.9624404 | I30: =H30 -> 3.9624404 | J30: =I30 -> 3.9624404 | K30: =J30 -> 3.9624404 | L30: =K30 -> 3.9624404 | M30: =L30 -> 3.9624404 | N30: =M30 -> 3.9624404 | O30: =N30 -> 3.9624404 | ... Q30: =P30 -> 3.9624404
B31: Unclaimed Dividend | C31: ='Historical FS'!C53 -> 0.1547499 | D31: ='Historical FS'!D53 -> 0.2840777 | E31: ='Historical FS'!E53 -> 0.3778478 | F31: ='Historical FS'!F53 -> 0.5752783 | G31: ='Historical FS'!G53 -> 0.7481253 | H31: =G31 -> 0.7481253 | I31: =H31 -> 0.7481253 | J31: =I31 -> 0.7481253 | K31: =J31 -> 0.7481253 | L31: =K31 -> 0.7481253 | M31: =L31 -> 0.7481253 | N31: =M31 -> 0.7481253 | O31: =N31 -> 0.7481253 | ... Q31: =P31 -> 0.7481253
B32: Total Current Liabilities | C32: =SUM(C26:C31) -> 3620.2409 | D32: =SUM(D26:D31) -> 5486.4281 | E32: =SUM(E26:E31) -> 3541.1203 | F32: =SUM(F26:F31) -> 3533.8202 | G32: =SUM(G26:G31) -> 2859.8966 | H32: =SUM(H26:H31) -> 3039.2223 | I32: =SUM(I26:I31) -> 3224.1901 | J32: =SUM(J26:J31) -> 3281.985 | ... Q32: =SUM(Q26:Q31) -> 3604.3166
B34: Non-Current Liabilities
B35: Long-term Debt | C35: ='Historical FS'!C56 -> 341.39273 | D35: ='Historical FS'!D56 -> 258.40659 | E35: ='Historical FS'!E56 -> 514.43276 | F35: ='Historical FS'!F56 -> 578.46689 | G35: ='Historical FS'!G56 -> 562.55482 | H35: ='Debt Schedule'!D23-'Balance Sheet'!H29 -> 562.55482 | I35: ='Debt Schedule'!E23-'Balance Sheet'!I29 -> 562.55482 | J35: ='Debt Schedule'!F23-'Balance Sheet'!J29 -> 562.55482 | K35: ='Debt Schedule'!G23-'Balance Sheet'!K29 -> 562.55482 | L35: ='Debt Schedule'!H23-'Balance Sheet'!L29 -> 562.55482 | M35: ='Debt Schedule'!I23-'Balance Sheet'!M29 -> 562.55482 | N35: ='Debt Schedule'!J23-'Balance Sheet'!N29 -> 562.55482 | O35: ='Debt Schedule'!K23-'Balance Sheet'!O29 -> 562.55482 | ... Q35: ='Debt Schedule'!M23-'Balance Sheet'!Q29 -> 562.55482
B36: Lease Liabilities | C36: ='Historical FS'!C57 -> 0 | D36: ='Historical FS'!D57 -> 18.948746 | E36: ='Historical FS'!E57 -> 19.612008 | F36: ='Historical FS'!F57 -> 18.695771 | G36: ='Historical FS'!G57 -> 19.946937 | H36: ='Debt Schedule'!D28-'Balance Sheet'!H30 -> 19.946937 | I36: ='Debt Schedule'!E28-'Balance Sheet'!I30 -> 19.946937 | J36: ='Debt Schedule'!F28-'Balance Sheet'!J30 -> 19.946937 | K36: ='Debt Schedule'!G28-'Balance Sheet'!K30 -> 19.946937 | L36: ='Debt Schedule'!H28-'Balance Sheet'!L30 -> 19.946937 | M36: ='Debt Schedule'!I28-'Balance Sheet'!M30 -> 19.946937 | N36: ='Debt Schedule'!J28-'Balance Sheet'!N30 -> 19.946937 | O36: ='Debt Schedule'!K28-'Balance Sheet'!O30 -> 19.946937 | ... Q36: ='Debt Schedule'!M28-'Balance Sheet'!Q30 -> 19.946937
B37: Deferred Tax Liabilities | C37: ='Historical FS'!C58 -> 36.546214 | D37: ='Historical FS'!D58 -> 47.768313 | E37: ='Historical FS'!E58 -> 98.945058 | F37: ='Historical FS'!F58 -> 96.71463 | G37: ='Historical FS'!G58 -> 201.94047 | H37: =G37 -> 201.94047 | I37: =H37 -> 201.94047 | J37: =I37 -> 201.94047 | K37: =J37 -> 201.94047 | L37: =K37 -> 201.94047 | M37: =L37 -> 201.94047 | N37: =M37 -> 201.94047 | O37: =N37 -> 201.94047 | ... Q37: =P37 -> 201.94047
B38: UNDP Fund | C38: ='Historical FS'!C59 -> 7.7603084 | D38: ='Historical FS'!D59 -> 5.7116262 | E38: ='Historical FS'!E59 -> 7.4329381 | F38: ='Historical FS'!F59 -> 7.4068576 | G38: ='Historical FS'!G59 -> 7.8824932 | H38: =G38 -> 7.8824932 | I38: =H38 -> 7.8824932 | J38: =I38 -> 7.8824932 | K38: =J38 -> 7.8824932 | L38: =K38 -> 7.8824932 | M38: =L38 -> 7.8824932 | N38: =M38 -> 7.8824932 | O38: =N38 -> 7.8824932 | ... Q38: =P38 -> 7.8824932
B39: Total Non-current Liabilities | C39: =SUM(C35:C38) -> 385.69925 | D39: =SUM(D35:D38) -> 330.83527 | E39: =SUM(E35:E38) -> 640.42276 | F39: =SUM(F35:F38) -> 701.28414 | G39: =SUM(G35:G38) -> 792.32473 | H39: =SUM(H35:H38) -> 792.32473 | I39: =SUM(I35:I38) -> 792.32473 | J39: =SUM(J35:J38) -> 792.32473 | ... Q39: =SUM(Q35:Q38) -> 792.32473
B41: Total Liabilities | C41: =C32+C39 -> 4005.9402 | D41: =D32+D39 -> 5817.2633 | E41: =E32+E39 -> 4181.543 | F41: =F32+F39 -> 4235.1044 | G41: =G32+G39 -> 3652.2213 | H41: =H32+H39 -> 3831.547 | I41: =I32+I39 -> 4016.5148 | J41: =J32+J39 -> 4074.3097 | ... Q41: =Q32+Q39 -> 4396.6413
B43: Shareholders' Equity
B44: Common Stock | C44: ='Historical FS'!C63 -> 302.92834 | D44: ='Historical FS'!D63 -> 302.92834 | E44: ='Historical FS'!E63 -> 302.92834 | F44: ='Historical FS'!F63 -> 302.92834 | G44: ='Historical FS'!G63 -> 302.92834 | H44: =G44 -> 302.92834 | I44: =H44 -> 302.92834 | J44: =I44 -> 302.92834 | K44: =J44 -> 302.92834 | L44: =K44 -> 302.92834 | M44: =L44 -> 302.92834 | N44: =M44 -> 302.92834 | O44: =N44 -> 302.92834 | ... Q44: =P44 -> 302.92834
